<?xml version="1.0" ?>
<!-- =================================================================================== -->
<!-- |    This document was autogenerated by xacro from /home/rumy/acrome_ws/install/acrome_mini_robot/share/acrome_mini_robot/urdf/acrome_mini_robot.urdf.xacro | -->
<!-- |    EDITING THIS FILE BY HAND IS NOT RECOMMENDED                                 | -->
<!-- =================================================================================== -->
<robot name="acrome_mini_robot">
  <!-- BASE LINK -->
  <link name="base_link">
    <inertial>
      <origin rpy="0 0 0" xyz="0.004817 0.018224 0.000192"/>
      <mass value="0.362984"/>
      <inertia ixx="0.000192" ixy="0" ixz="0" iyy="0.000626" iyz="0" izz="0.000789"/>
    </inertial>
    <visual>
      <origin rpy="0 0 0" xyz="0 0 0"/>
      <geometry>
        <mesh filename="package://acrome_mini_robot/meshes/base_link.stl"/>
      </geometry>
      <material name="default">
        <color rgba="0.792156 0.819607 0.933333 1"/>
      </material>
    </visual>
    <collision>
      <origin rpy="0 0 0" xyz="0 0 0"/>
      <geometry>
        <mesh filename="package://acrome_mini_robot/meshes/base_link.stl"/>
      </geometry>
    </collision>
  </link>
  <!-- LEFT WHEEL -->
  <link name="left_wheel">
    <inertial>
      <origin rpy="0 0 0" xyz="0.006001 -0.000499 0.000223"/>
      <mass value="0.031169"/>
      <inertia ixx="0.000002" ixy="0" ixz="0" iyy="0.000001" iyz="0" izz="0.000001"/>
    </inertial>
    <visual>
      <origin rpy="0 0 0" xyz="0 0 0"/>
      <geometry>
        <mesh filename="package://acrome_mini_robot/meshes/left_wheel.stl"/>
      </geometry>
      <material name="default">
        <color rgba="0.792156 0.819607 0.933333 1"/>
      </material>
    </visual>
    <collision>
      <origin rpy="0 0 0" xyz="0 0 0"/>
      <geometry>
        <mesh filename="package://acrome_mini_robot/meshes/left_wheel.stl"/>
      </geometry>
    </collision>
  </link>
  <joint name="leftwheel" type="continuous">
    <origin rpy="0 0 0" xyz="-0.14277 -5.9761E-05 -0.01126"/>
    <parent link="base_link"/>
    <child link="left_wheel"/>
    <axis xyz="-1 0 0"/>
    <limit effort="10" velocity="10"/>
    <dynamics damping="0.1" friction="0.1"/>
  </joint>
  <!-- RIGHT WHEEL -->
  <link name="right_wheel">
    <inertial>
      <origin rpy="0 0 0" xyz="-0.00600143 0.00051155 -0.00019463"/>
      <mass value="0.031169"/>
      <inertia ixx="0.000002" ixy="0" ixz="0" iyy="0.000001" iyz="0" izz="0.000001"/>
    </inertial>
    <visual>
      <origin rpy="0 0 0" xyz="0 0 0"/>
      <geometry>
        <mesh filename="package://acrome_mini_robot/meshes/right_wheel.stl"/>
      </geometry>
      <material name="default">
        <color rgba="0.792156 0.819607 0.933333 1"/>
      </material>
    </visual>
    <collision>
      <origin rpy="0 0 0" xyz="0 0 0"/>
      <geometry>
        <mesh filename="package://acrome_mini_robot/meshes/right_wheel.stl"/>
      </geometry>
    </collision>
  </link>
  <joint name="rightwheel" type="continuous">
    <origin rpy="0 0 0" xyz="0.14283 -5.9761E-05 -0.01126"/>
    <parent link="base_link"/>
    <child link="right_wheel"/>
    <axis xyz="1 0 0"/>
    <limit effort="10" velocity="10"/>
    <dynamics damping="0.1" friction="0.1"/>
  </joint>
  <!-- TRANSMISSIONS -->
  <transmission name="leftwheel_trans">
    <type>transmission_interface/SimpleTransmission</type>
    <joint name="leftwheel">
      <hardwareInterface>hardware_interface/VelocityJointInterface</hardwareInterface>
    </joint>
    <actuator name="leftwheel_motor">
      <hardwareInterface>hardware_interface/VelocityJointInterface</hardwareInterface>
      <mechanicalReduction>1</mechanicalReduction>
    </actuator>
  </transmission>
  <transmission name="rightwheel_trans">
    <type>transmission_interface/SimpleTransmission</type>
    <joint name="rightwheel">
      <hardwareInterface>hardware_interface/VelocityJointInterface</hardwareInterface>
    </joint>
    <actuator name="rightwheel_motor">
      <hardwareInterface>hardware_interface/VelocityJointInterface</hardwareInterface>
      <mechanicalReduction>1</mechanicalReduction>
    </actuator>
  </transmission>
  <!-- GAZEBO ROS2 CONTROL PLUGIN -->
  <gazebo>
    <plugin filename="libgazebo_ros2_control.so" name="gazebo_ros2_control"/>
  </gazebo>
  <!-- ROS2_CONTROL INTERFACE EKLENDİ -->
  <ros2_control name="AcromeMiniBotController" type="system">
    <hardware>
      <plugin>gazebo_ros2_control/GazeboSystem</plugin>
    </hardware>
    <joint>
      <name>leftwheel</name>
      <command_interface>velocity</command_interface>
      <state_interface>velocity</state_interface>
    </joint>
    <joint>
      <name>rightwheel</name>
      <command_interface>velocity</command_interface>
      <state_interface>velocity</state_interface>
    </joint>
  </ros2_control>
</robot>
