<?xml version="1.0" ?>
<robot name="acrome_mini_robot">
  
  <!-- Ana robot gövdesi -->
  <link name="base_link">
    <visual>
      <geometry>
        <cylinder radius="0.25" length="0.15"/>
      </geometry>
      <origin xyz="0 0 0.075" rpy="0 0 0"/>
      <material name="blue">
        <color rgba="0.2 0.2 0.8 1"/>
      </material>
    </visual>
    <collision>
      <geometry>
        <cylinder radius="0.25" length="0.15"/>
      </geometry>
      <origin xyz="0 0 0.075" rpy="0 0 0"/>
    </collision>
    <inertial>
      <mass value="5.0"/>
      <origin xyz="0 0 0.075" rpy="0 0 0"/>
      <inertia ixx="0.2083" ixy="0.0" ixz="0.0" iyy="0.2083" iyz="0.0" izz="0.3125"/>
    </inertial>
  </link>

  <!-- Tekerlek 1 (Ön tekerlek - 0 derece) -->
  <link name="wheel_1">
    <visual>
      <geometry>
        <cylinder radius="0.08" length="0.04"/>
      </geometry>
      <origin xyz="0 0 0" rpy="1.5708 0 0"/>
      <material name="black">
        <color rgba="0.1 0.1 0.1 1"/>
      </material>
    </visual>
    <collision>
      <geometry>
        <cylinder radius="0.08" length="0.04"/>
      </geometry>
      <origin xyz="0 0 0" rpy="1.5708 0 0"/>
    </collision>
    <inertial>
      <mass value="0.5"/>
      <origin xyz="0 0 0" rpy="0 0 0"/>
      <inertia ixx="0.0032" ixy="0.0" ixz="0.0" iyy="0.0032" iyz="0.0" izz="0.0032"/>
    </inertial>
  </link>

  <!-- Tekerlek 2 (Sol arka - 120 derece) -->
  <link name="wheel_2">
    <visual>
      <geometry>
        <cylinder radius="0.08" length="0.04"/>
      </geometry>
      <origin xyz="0 0 0" rpy="1.5708 0 0"/>
      <material name="black">
        <color rgba="0.1 0.1 0.1 1"/>
      </material>
    </visual>
    <collision>
      <geometry>
        <cylinder radius="0.08" length="0.04"/>
      </geometry>
      <origin xyz="0 0 0" rpy="1.5708 0 0"/>
    </collision>
    <inertial>
      <mass value="0.5"/>
      <origin xyz="0 0 0" rpy="0 0 0"/>
      <inertia ixx="0.0032" ixy="0.0" ixz="0.0" iyy="0.0032" iyz="0.0" izz="0.0032"/>
    </inertial>
  </link>

  <!-- Tekerlek 3 (Sağ arka - 240 derece) -->
  <link name="wheel_3">
    <visual>
      <geometry>
        <cylinder radius="0.08" length="0.04"/>
      </geometry>
      <origin xyz="0 0 0" rpy="1.5708 0 0"/>
      <material name="black">
        <color rgba="0.1 0.1 0.1 1"/>
      </material>
    </visual>
    <collision>
      <geometry>
        <cylinder radius="0.08" length="0.04"/>
      </geometry>
      <origin xyz="0 0 0" rpy="1.5708 0 0"/>
    </collision>
    <inertial>
      <mass value="0.5"/>
      <origin xyz="0 0 0" rpy="0 0 0"/>
      <inertia ixx="0.0032" ixy="0.0" ixz="0.0" iyy="0.0032" iyz="0.0" izz="0.0032"/>
    </inertial>
  </link>

  <!-- Tekerlek joint'leri -->
  <joint name="base_to_wheel_1" type="continuous">
    <parent link="base_link"/>
    <child link="wheel_1"/>
    <origin xyz="0.2 0 0" rpy="0 0 0"/>
    <axis xyz="0 1 0"/>
    <dynamics damping="0.7" friction="0.1"/>
  </joint>

  <joint name="base_to_wheel_2" type="continuous">
    <parent link="base_link"/>
    <child link="wheel_2"/>
    <origin xyz="-0.1 0.173 0" rpy="0 0 2.094"/>
    <axis xyz="0 1 0"/>
    <dynamics damping="0.7" friction="0.1"/>
  </joint>

  <joint name="base_to_wheel_3" type="continuous">
    <parent link="base_link"/>
    <child link="wheel_3"/>
    <origin xyz="-0.1 -0.173 0" rpy="0 0 -2.094"/>
    <axis xyz="0 1 0"/>
    <dynamics damping="0.7" friction="0.1"/>
  </joint>

  <!-- IMU sensörü -->
  <link name="imu_link">
    <inertial>
      <mass value="0.001"/>
      <origin xyz="0 0 0" rpy="0 0 0"/>
      <inertia ixx="0.0001" ixy="0" ixz="0" iyy="0.0001" iyz="0" izz="0.0001"/>
    </inertial>
    <visual>
      <geometry>
        <box size="0.01 0.01 0.01"/>
      </geometry>
      <material name="red">
        <color rgba="1 0 0 1"/>
      </material>
    </visual>
  </link>

  <joint name="base_to_imu" type="fixed">
    <parent link="base_link"/>
    <child link="imu_link"/>
    <origin xyz="0.0 0.0 0.15"/>
  </joint>

  <!-- ROS2 Control -->
  <ros2_control name="GazeboSimSystem" type="system">
    <hardware>
      <plugin>gz_ros2_control/GazeboSimSystem</plugin>
    </hardware>
    
    <joint name="base_to_wheel_1">
      <command_interface name="velocity">
        <param name="min">-10</param>
        <param name="max">10</param>
      </command_interface>
      <state_interface name="position"/>
      <state_interface name="velocity"/>
      <state_interface name="effort"/>
    </joint>

    <joint name="base_to_wheel_2">
      <command_interface name="velocity">
        <param name="min">-10</param>
        <param name="max">10</param>
      </command_interface>
      <state_interface name="position"/>
      <state_interface name="velocity"/>
      <state_interface name="effort"/>
    </joint>

    <joint name="base_to_wheel_3">
      <command_interface name="velocity">
        <param name="min">-10</param>
        <param name="max">10</param>
      </command_interface>
      <state_interface name="position"/>
      <state_interface name="velocity"/>
      <state_interface name="effort"/>
    </joint>
  </ros2_control>

  <!-- Gazebo pluginleri -->
  <gazebo>
    <plugin filename="gz_ros2_control-system" name="gz_ros2_control::GazeboSimROS2ControlPlugin">
      <parameters>$(find acrome_mini_robot)/config/acrome_controller.yaml</parameters>
    </plugin>
  </gazebo>

  <!-- Gazebo specific ayarları -->
  <gazebo reference="base_link">
    <mu1>0.2</mu1>
    <mu2>0.2</mu2>
    <material>Gazebo/Blue</material>
  </gazebo>

  <gazebo reference="wheel_1">
    <mu1>1.0</mu1>
    <mu2>1.0</mu2>
    <kp>1000000.0</kp>
    <kd>100.0</kd>
    <material>Gazebo/Black</material>
  </gazebo>

  <gazebo reference="wheel_2">
    <mu1>1.0</mu1>
    <mu2>1.0</mu2>
    <kp>1000000.0</kp>
    <kd>100.0</kd>
    <material>Gazebo/Black</material>
  </gazebo>

  <gazebo reference="wheel_3">
    <mu1>1.0</mu1>
    <mu2>1.0</mu2>
    <kp>1000000.0</kp>
    <kd>100.0</kd>
    <material>Gazebo/Black</material>
  </gazebo>

  <gazebo reference="imu_link">
    <gravity>true</gravity>
    <sensor name="imu_sensor" type="imu">
      <always_on>1</always_on>
      <update_rate>100</update_rate>
      <visualize>true</visualize>
      <topic>__default_topic__</topic>
      <plugin filename="libgazebo_ros_imu_sensor.so" name="imu_plugin">
        <topicName>imu</topicName>
        <bodyName>imu_link</bodyName>
        <updateRateHZ>10.0</updateRateHZ>
        <gaussianNoise>0.0</gaussianNoise>
        <xyzOffset>0 0 0</xyzOffset>
        <rpyOffset>0 0 0</rpyOffset>
        <frameName>imu_link</frameName>
      </plugin>
      <pose>0 0 0 0 0 0</pose>
    </sensor>
  </gazebo>

</robot>